outputs/trades_InventorySkew_BuyPressure.csv
timestamp,strategy,regime,price,quantity,mm_bought,mm_sold
1,InventorySkew,BuyPressure,100.050000,12,0,0
2,InventorySkew,BuyPressure,99.950000,13,0,0
3,InventorySkew,BuyPressure,100.050000,5,0,0
4,InventorySkew,BuyPressure,99.950000,4,0,0
5,InventorySkew,BuyPressure,99.950000,7,0,0
6,InventorySkew,BuyPressure,99.950000,2,0,0
7,InventorySkew,BuyPressure,100.050000,20,0,0
9,InventorySkew,BuyPressure,100.050000,13,0,0
9,InventorySkew,BuyPressure,100.100000,1,0,0
10,InventorySkew,BuyPressure,100.100000,3,0,0
11,InventorySkew,BuyPressure,100.055489,10,0,1
11,InventorySkew,BuyPressure,100.100000,9,0,0
13,InventorySkew,BuyPressure,100.100000,3,0,0
14,InventorySkew,BuyPressure,99.955489,3,1,0
16,InventorySkew,BuyPressure,100.075470,2,0,0
16,InventorySkew,BuyPressure,100.100000,11,0,0
17,InventorySkew,BuyPressure,100.100000,20,0,0
19,InventorySkew,BuyPressure,100.100000,3,0,0
19,InventorySkew,BuyPressure,100.150000,14,0,0
20,InventorySkew,BuyPressure,99.955489,5,1,0
21,InventorySkew,BuyPressure,100.125584,10,0,1
21,InventorySkew,BuyPressure,100.150000,10,0,0
22,InventorySkew,BuyPressure,100.150000,3,0,0
23,InventorySkew,BuyPressure,100.150000,8,0,0
24,InventorySkew,BuyPressure,100.150000,7,0,0
28,InventorySkew,BuyPressure,100.144852,1,0,0
28,InventorySkew,BuyPressure,100.150000,8,0,0
28,InventorySkew,BuyPressure,100.180260,4,0,0
30,InventorySkew,BuyPressure,100.180260,3,0,0
30,InventorySkew,BuyPressure,100.196948,1,0,0
30,InventorySkew,BuyPressure,100.196948,10,1,0
31,InventorySkew,BuyPressure,100.196948,9,0,0
31,InventorySkew,BuyPressure,100.200000,2,0,0
32,InventorySkew,BuyPressure,100.200000,13,0,0
33,InventorySkew,BuyPressure,100.025584,9,1,0
34,InventorySkew,BuyPressure,100.025584,1,1,0
34,InventorySkew,BuyPressure,99.976379,2,0,0
34,InventorySkew,BuyPressure,99.955489,2,1,0
34,InventorySkew,BuyPressure,99.950000,4,0,0
36,InventorySkew,BuyPressure,99.953531,11,0,0
36,InventorySkew,BuyPressure,99.950000,7,0,0
37,InventorySkew,BuyPressure,100.200000,10,0,0
39,InventorySkew,BuyPressure,100.200000,15,0,0
41,InventorySkew,BuyPressure,100.029661,10,0,1
41,InventorySkew,BuyPressure,100.200000,2,0,0
42,InventorySkew,BuyPressure,100.200000,4,0,0
45,InventorySkew,BuyPressure,100.169251,6,0,0
45,InventorySkew,BuyPressure,100.200000,3,0,0
48,InventorySkew,BuyPressure,100.140181,7,0,0
48,InventorySkew,BuyPressure,100.086337,8,0,0
49,InventorySkew,BuyPressure,100.086337,4,0,0
49,InventorySkew,BuyPressure,99.950000,3,0,0
50,InventorySkew,BuyPressure,99.950000,10,0,0
50,InventorySkew,BuyPressure,99.945944,5,0,0
51,InventorySkew,BuyPressure,100.181187,10,0,1
52,InventorySkew,BuyPressure,100.081187,1,1,0
54,InventorySkew,BuyPressure,100.087283,4,0,0
55,InventorySkew,BuyPressure,100.200000,1,0,0
55,InventorySkew,BuyPressure,100.211862,1,0,0
58,InventorySkew,BuyPressure,100.211862,16,0,0
58,InventorySkew,BuyPressure,100.221977,1,0,0
60,InventorySkew,BuyPressure,100.221977,4,0,0
60,InventorySkew,BuyPressure,100.249452,4,0,0
60,InventorySkew,BuyPressure,100.250000,1,0,0
61,InventorySkew,BuyPressure,100.250000,2,0,0
65,InventorySkew,BuyPressure,100.242042,10,1,0
65,InventorySkew,BuyPressure,100.087283,8,0,0
65,InventorySkew,BuyPressure,100.081187,1,1,0
66,InventorySkew,BuyPressure,100.250000,2,0,0
67,InventorySkew,BuyPressure,100.081187,8,1,0
68,InventorySkew,BuyPressure,100.077381,6,0,0
69,InventorySkew,BuyPressure,100.250000,19,0,0
70,InventorySkew,BuyPressure,100.077381,2,0,0
70,InventorySkew,BuyPressure,100.077381,1,0,1
70,InventorySkew,BuyPressure,100.069807,9,0,1
72,InventorySkew,BuyPressure,100.250000,12,0,0
73,InventorySkew,BuyPressure,100.250000,11,0,0
77,InventorySkew,BuyPressure,100.240889,11,0,0
77,InventorySkew,BuyPressure,100.250000,3,0,0
77,InventorySkew,BuyPressure,100.263942,4,0,0
79,InventorySkew,BuyPressure,100.069807,6,0,0
79,InventorySkew,BuyPressure,100.054988,10,0,0
80,InventorySkew,BuyPressure,100.263942,1,0,0
80,InventorySkew,BuyPressure,100.300000,17,0,0
81,InventorySkew,BuyPressure,100.216808,10,0,1
81,InventorySkew,BuyPressure,100.300000,3,0,0
84,InventorySkew,BuyPressure,100.300000,12,0,0
85,InventorySkew,BuyPressure,100.300000,1,0,0
86,InventorySkew,BuyPressure,100.131220,15,0,0
86,InventorySkew,BuyPressure,100.116808,4,1,0
89,InventorySkew,BuyPressure,100.116808,6,1,0
89,InventorySkew,BuyPressure,100.103449,10,0,0
90,InventorySkew,BuyPressure,100.300000,17,0,0
90,InventorySkew,BuyPressure,100.334232,2,0,0
91,InventorySkew,BuyPressure,100.128004,10,1,0
93,InventorySkew,BuyPressure,100.228004,4,0,1
94,InventorySkew,BuyPressure,100.228004,6,0,1
95,InventorySkew,BuyPressure,100.276690,7,0,0
95,InventorySkew,BuyPressure,100.334232,4,0,0
96,InventorySkew,BuyPressure,100.334232,12,0,0
97,InventorySkew,BuyPressure,100.103449,6,0,0
97,InventorySkew,BuyPressure,100.054988,9,0,0
97,InventorySkew,BuyPressure,100.052720,3,0,0
98,InventorySkew,BuyPressure,100.052720,3,0,0
98,InventorySkew,BuyPressure,100.019999,5,0,0
98,InventorySkew,BuyPressure,100.018728,4,0,0
99,InventorySkew,BuyPressure,100.334232,2,0,0
99,InventorySkew,BuyPressure,100.342042,5,0,1
100,InventorySkew,BuyPressure,100.342042,5,0,1
100,InventorySkew,BuyPressure,100.350000,13,0,0
103,InventorySkew,BuyPressure,100.350000,3,0,0
107,InventorySkew,BuyPressure,100.350000,5,0,0
110,InventorySkew,BuyPressure,100.336981,2,0,0
110,InventorySkew,BuyPressure,100.336981,3,1,0
112,InventorySkew,BuyPressure,100.349349,7,1,0
112,InventorySkew,BuyPressure,100.323913,5,1,0
113,InventorySkew,BuyPressure,100.323913,5,1,0
113,InventorySkew,BuyPressure,100.203107,14,0,0
114,InventorySkew,BuyPressure,100.350000,15,0,0
115,InventorySkew,BuyPressure,100.203107,1,0,0
115,InventorySkew,BuyPressure,100.160252,15,0,0
116,InventorySkew,BuyPressure,100.350000,12,0,0
117,InventorySkew,BuyPressure,100.160252,1,0,0
117,InventorySkew,BuyPressure,100.135625,4,0,0
118,InventorySkew,BuyPressure,100.135625,4,0,0
120,InventorySkew,BuyPressure,100.350000,2,0,0
120,InventorySkew,BuyPressure,100.350235,3,0,1
123,InventorySkew,BuyPressure,100.158538,10,0,1
123,InventorySkew,BuyPressure,100.298707,5,0,0
123,InventorySkew,BuyPressure,100.350235,1,0,1
124,InventorySkew,BuyPressure,100.350235,6,0,1
124,InventorySkew,BuyPressure,100.370446,13,0,0
126,InventorySkew,BuyPressure,100.165769,12,0,0
127,InventorySkew,BuyPressure,100.381015,14,0,0
129,InventorySkew,BuyPressure,100.371389,7,0,0
131,InventorySkew,BuyPressure,100.337763,9,1,0
132,InventorySkew,BuyPressure,100.337763,1,1,0
132,InventorySkew,BuyPressure,100.224225,5,0,0
132,InventorySkew,BuyPressure,100.165769,1,0,0
132,InventorySkew,BuyPressure,100.124594,5,0,0
134,InventorySkew,BuyPressure,100.249700,5,0,0
136,InventorySkew,BuyPressure,100.249700,8,0,0
136,InventorySkew,BuyPressure,100.357829,2,0,0
137,InventorySkew,BuyPressure,100.357829,12,0,0
139,InventorySkew,BuyPressure,100.357829,3,0,0
139,InventorySkew,BuyPressure,100.371389,9,0,0
139,InventorySkew,BuyPressure,100.381015,5,0,0
140,InventorySkew,BuyPressure,100.381015,1,0,0
140,InventorySkew,BuyPressure,100.400000,18,0,0
150,InventorySkew,BuyPressure,100.228440,10,1,0
150,InventorySkew,BuyPressure,100.196212,2,0,0
150,InventorySkew,BuyPressure,100.196103,6,0,0
150,InventorySkew,BuyPressure,100.196103,10,0,1
156,InventorySkew,BuyPressure,100.314332,3,0,0
156,InventorySkew,BuyPressure,100.328440,10,0,1
156,InventorySkew,BuyPressure,100.340314,3,0,0
157,InventorySkew,BuyPressure,100.340314,2,0,0
157,InventorySkew,BuyPressure,100.355005,2,0,0
157,InventorySkew,BuyPressure,100.400000,6,0,0
158,InventorySkew,BuyPressure,100.400000,15,0,0
162,InventorySkew,BuyPressure,100.400000,8,0,0
164,InventorySkew,BuyPressure,100.400000,3,0,0
165,InventorySkew,BuyPressure,100.403934,6,0,0
166,InventorySkew,BuyPressure,100.392866,4,1,0
167,InventorySkew,BuyPressure,100.423913,10,0,1
167,InventorySkew,BuyPressure,100.437763,3,0,1
169,InventorySkew,BuyPressure,100.437763,7,0,1
169,InventorySkew,BuyPressure,100.449349,10,0,1
169,InventorySkew,BuyPressure,100.450000,1,0,0
170,InventorySkew,BuyPressure,100.450000,12,0,0
170,InventorySkew,BuyPressure,100.450000,10,1,0
