outputs/trades_InventorySkew_SellPressure.csv
timestamp,strategy,regime,price,quantity,mm_bought,mm_sold
1,InventorySkew,SellPressure,99.950000,5,0,0
2,InventorySkew,SellPressure,100.050000,2,0,0
3,InventorySkew,SellPressure,99.950000,20,0,0
7,InventorySkew,SellPressure,99.951333,9,0,0
7,InventorySkew,SellPressure,99.950000,2,0,0
10,InventorySkew,SellPressure,99.950000,4,0,0
11,InventorySkew,SellPressure,99.950000,10,0,0
15,InventorySkew,SellPressure,99.999555,4,0,1
16,InventorySkew,SellPressure,99.999555,4,0,1
17,InventorySkew,SellPressure,99.999555,2,0,1
17,InventorySkew,SellPressure,100.009057,10,0,0
17,InventorySkew,SellPressure,100.040436,7,0,0
18,InventorySkew,SellPressure,99.950000,3,0,0
20,InventorySkew,SellPressure,100.040436,3,1,0
20,InventorySkew,SellPressure,100.050000,7,1,0
22,InventorySkew,SellPressure,99.950000,6,0,0
22,InventorySkew,SellPressure,99.900000,4,0,0
23,InventorySkew,SellPressure,99.900000,13,0,0
24,InventorySkew,SellPressure,99.900000,8,0,0
26,InventorySkew,SellPressure,99.900000,2,0,0
27,InventorySkew,SellPressure,100.050000,17,0,0
28,InventorySkew,SellPressure,99.900000,11,0,0
29,InventorySkew,SellPressure,99.900000,12,0,0
29,InventorySkew,SellPressure,99.899555,8,1,0
30,InventorySkew,SellPressure,100.050000,15,0,0
30,InventorySkew,SellPressure,99.899555,2,1,1
30,InventorySkew,SellPressure,99.850000,8,0,1
33,InventorySkew,SellPressure,99.850000,3,0,0
34,InventorySkew,SellPressure,99.850000,13,0,0
36,InventorySkew,SellPressure,99.850000,17,0,0
45,InventorySkew,SellPressure,99.863749,14,0,0
45,InventorySkew,SellPressure,99.896876,6,0,1
48,InventorySkew,SellPressure,99.850000,9,0,0
51,InventorySkew,SellPressure,99.896876,4,0,1
51,InventorySkew,SellPressure,99.909342,3,0,0
51,InventorySkew,SellPressure,99.929460,11,0,0
53,InventorySkew,SellPressure,99.890072,10,1,0
54,InventorySkew,SellPressure,99.929460,1,0,0
54,InventorySkew,SellPressure,99.930306,7,0,0
55,InventorySkew,SellPressure,99.839761,10,0,0
56,InventorySkew,SellPressure,99.839761,1,0,0
56,InventorySkew,SellPressure,99.800000,11,0,0
57,InventorySkew,SellPressure,99.930306,10,0,0
57,InventorySkew,SellPressure,99.941530,2,0,0
58,InventorySkew,SellPressure,99.800000,1,0,0
59,InventorySkew,SellPressure,99.941530,6,0,0
61,InventorySkew,SellPressure,99.809650,8,1,0
62,InventorySkew,SellPressure,99.909650,10,0,1
64,InventorySkew,SellPressure,99.809650,2,1,0
64,InventorySkew,SellPressure,99.800000,11,0,0
69,InventorySkew,SellPressure,99.941530,10,0,0
69,InventorySkew,SellPressure,99.961776,1,0,0
69,InventorySkew,SellPressure,99.964381,1,0,0
70,InventorySkew,SellPressure,99.812008,15,0,0
72,InventorySkew,SellPressure,99.812008,5,0,0
72,InventorySkew,SellPressure,99.802779,10,1,0
72,InventorySkew,SellPressure,99.800000,1,0,0
73,InventorySkew,SellPressure,99.800000,19,0,0
74,InventorySkew,SellPressure,99.902779,10,0,1
74,InventorySkew,SellPressure,99.964381,1,0,0
74,InventorySkew,SellPressure,99.971944,6,0,0
75,InventorySkew,SellPressure,99.971944,8,0,0
76,InventorySkew,SellPressure,99.800000,7,0,0
76,InventorySkew,SellPressure,99.796876,7,1,0
77,InventorySkew,SellPressure,99.796876,2,1,0
80,InventorySkew,SellPressure,99.796876,1,1,0
80,InventorySkew,SellPressure,99.792659,12,0,0
80,InventorySkew,SellPressure,99.787621,10,0,1
82,InventorySkew,SellPressure,99.775139,12,0,0
82,InventorySkew,SellPressure,99.763105,1,0,0
83,InventorySkew,SellPressure,99.763105,1,0,0
83,InventorySkew,SellPressure,99.763101,6,0,0
84,InventorySkew,SellPressure,99.763101,6,0,0
84,InventorySkew,SellPressure,99.752826,4,0,0
86,InventorySkew,SellPressure,99.752826,10,0,0
86,InventorySkew,SellPressure,99.750000,5,0,0
88,InventorySkew,SellPressure,99.750000,3,0,0
89,InventorySkew,SellPressure,99.750000,3,0,0
91,InventorySkew,SellPressure,99.750000,11,0,0
92,InventorySkew,SellPressure,99.797956,4,0,1
93,InventorySkew,SellPressure,99.750000,1,0,0
94,InventorySkew,SellPressure,99.750000,6,0,0
98,InventorySkew,SellPressure,99.750000,10,0,0
103,InventorySkew,SellPressure,99.750000,9,0,0
104,InventorySkew,SellPressure,99.795512,8,0,0
104,InventorySkew,SellPressure,99.797956,1,0,1
105,InventorySkew,SellPressure,99.750000,2,0,0
106,InventorySkew,SellPressure,99.725612,10,1,0
106,InventorySkew,SellPressure,99.724803,5,1,0
107,InventorySkew,SellPressure,99.797956,5,0,1
107,InventorySkew,SellPressure,99.810933,3,0,0
108,InventorySkew,SellPressure,99.810933,17,0,0
108,InventorySkew,SellPressure,99.818827,3,0,0
109,InventorySkew,SellPressure,99.724803,5,1,0
109,InventorySkew,SellPressure,99.708086,2,0,0
110,InventorySkew,SellPressure,99.708086,11,0,0
110,InventorySkew,SellPressure,99.700000,6,0,0
110,InventorySkew,SellPressure,99.700000,10,0,1
112,InventorySkew,SellPressure,99.824803,10,0,1
112,InventorySkew,SellPressure,99.836695,4,0,0
113,InventorySkew,SellPressure,99.700000,6,0,0
119,InventorySkew,SellPressure,99.700000,17,0,0
120,InventorySkew,SellPressure,99.758005,10,1,0
121,InventorySkew,SellPressure,99.700000,11,0,0
121,InventorySkew,SellPressure,99.698014,1,0,0
121,InventorySkew,SellPressure,99.697956,3,1,0
122,InventorySkew,SellPressure,99.697956,7,1,0
122,InventorySkew,SellPressure,99.690290,12,0,0
123,InventorySkew,SellPressure,99.690290,4,0,0
123,InventorySkew,SellPressure,99.673879,2,0,0
130,InventorySkew,SellPressure,99.673879,10,0,1
134,InventorySkew,SellPressure,99.687450,1,0,0
137,InventorySkew,SellPressure,99.673879,3,0,0
137,InventorySkew,SellPressure,99.668927,2,0,0
138,InventorySkew,SellPressure,99.668927,6,0,0
139,InventorySkew,SellPressure,99.668927,8,0,0
140,InventorySkew,SellPressure,99.668927,3,0,0
140,InventorySkew,SellPressure,99.667761,5,0,1
140,InventorySkew,SellPressure,99.662537,5,0,1
142,InventorySkew,SellPressure,99.686213,8,0,0
142,InventorySkew,SellPressure,99.687450,4,0,0
142,InventorySkew,SellPressure,99.706087,2,0,0
143,InventorySkew,SellPressure,99.650000,5,0,0
144,InventorySkew,SellPressure,99.650000,13,0,0
146,InventorySkew,SellPressure,99.650000,14,0,0
148,InventorySkew,SellPressure,99.650000,12,0,0
149,InventorySkew,SellPressure,99.650000,6,0,0
149,InventorySkew,SellPressure,99.642902,12,0,0
151,InventorySkew,SellPressure,99.679259,17,0,0
151,InventorySkew,SellPressure,99.706087,3,0,0
152,InventorySkew,SellPressure,99.706087,8,0,0
153,InventorySkew,SellPressure,99.706087,3,0,0
153,InventorySkew,SellPressure,99.730226,8,0,0
153,InventorySkew,SellPressure,99.731118,1,0,1
154,InventorySkew,SellPressure,99.642902,2,0,0
154,InventorySkew,SellPressure,99.631118,4,1,0
156,InventorySkew,SellPressure,99.731118,9,0,1
156,InventorySkew,SellPressure,99.735845,3,0,0
157,InventorySkew,SellPressure,99.631118,6,1,0
157,InventorySkew,SellPressure,99.615443,10,1,0
157,InventorySkew,SellPressure,99.614940,1,0,0
158,InventorySkew,SellPressure,99.614940,7,0,0
158,InventorySkew,SellPressure,99.604796,5,0,0
159,InventorySkew,SellPressure,99.604796,5,0,0
160,InventorySkew,SellPressure,99.735845,14,0,0
160,InventorySkew,SellPressure,99.735998,6,0,0
162,InventorySkew,SellPressure,99.604796,4,0,0
162,InventorySkew,SellPressure,99.600000,4,0,0
165,InventorySkew,SellPressure,99.616352,3,0,1
167,InventorySkew,SellPressure,99.600000,16,0,0
168,InventorySkew,SellPressure,99.600000,17,0,0
169,InventorySkew,SellPressure,99.600000,8,0,0
172,InventorySkew,SellPressure,99.600000,5,0,0
172,InventorySkew,SellPressure,99.583912,4,0,0
174,InventorySkew,SellPressure,99.616352,7,0,1
174,InventorySkew,SellPressure,99.626201,7,0,0
176,InventorySkew,SellPressure,99.583912,5,0,0
176,InventorySkew,SellPressure,99.556032,9,0,0
177,InventorySkew,SellPressure,99.556032,5,0,0
177,InventorySkew,SellPressure,99.550000,6,0,0
179,InventorySkew,SellPressure,99.550000,16,0,0
180,InventorySkew,SellPressure,99.550556,2,0,0
180,InventorySkew,SellPressure,99.626201,5,0,0
180,InventorySkew,SellPressure,99.626201,8,1,0
180,InventorySkew,SellPressure,99.628614,2,1,1
181,InventorySkew,SellPressure,99.550000,13,0,0
182,InventorySkew,SellPressure,99.550000,1,0,0
183,InventorySkew,SellPressure,99.550000,14,0,0
183,InventorySkew,SellPressure,99.530013,1,1,0
184,InventorySkew,SellPressure,99.628614,6,0,1
